Workbook
Name Slicer_country: #N/A
Name Slicer_year: #N/A
Name Slicer_year1: #N/A

Sheet Sheet10
A2: country | B2: (Multiple Items)
A4: Row Labels | B4: Average of energy_per_capita
A5: 2000 | B5: 7479.4503
A6: 2001 | B6: 7551.104
A7: 2002 | B7: 7647.7177
A8: 2003 | B8: 7843.4517
A9: 2004 | B9: 8166.818
A10: 2005 | B10: 8741.3093
A11: 2006 | B11: 8467.6667
A12: 2007 | B12: 7676.0423
A13: 2008 | B13: 7889.5887
A14: 2009 | B14: 7385.8977
A15: 2010 | B15: 7529.5923
A16: 2011 | B16: 7417.0273
... A28: 2023 | B28: 7112.6033
A29: Grand Total | B29: 7653.062

Sheet Sheet11

Sheet EnergyData
A1: country | B1: year | C1: iso_code | D1: region | E1: income_group | F1: population | G1: gdp | H1: electricity_generation | I1: electricity_demand | J1: electricity_demand_per_capita | K1: net_elec_imports | L1: net_elec_imports_share_demand | M1: gas_production | N1: gas_consumption | O1: gas_prod_per_capita | P1: gas_share_elec | Q1: gas_share_energy | R1: oil_production | S1: oil_consumption | T1: renewables_electricity | U1: renewables_share_elec | V1: fossil_electricity | W1: fossil_share_elec | X1: energy_per_capita | Y1: greenhouse_gas_emissions | Z1: gdp_worldbank_usd
A2: Algeria | B2: 2000 | C2: DZA | D2: Middle East & North Africa | E2: Upper middle income | F2: 30903894 | G2: 208554000000 | H2: 25.4 | I2: 25.33 | J2: 819.638 | K2: -0.07 | L2: -0.276 | M2: 918.886 | N2: 191.013 | O2: 29733.676 | P2: 96.772 | Q2: 63.685 | R2: 776.733 | S2: 103.132 | T2: 0.05 | U2: 0.197 | V2: 25.35 | W2: 99.803 | X2: 9705.756 | Y2: 16.22 | Z2: 54790398570
A3: Algeria | B3: 2001 | C3: DZA | D3: Middle East & North Africa | E3: Upper middle income | F3: 31331226 | G3: 223420000000 | H3: 26.62 | I3: 26.57 | J3: 848.036 | K3: -0.05 | L3: -0.188 | M3: 864.725 | N3: 197.322 | O3: 27599.475 | P3: 96.844 | Q3: 63.488 | R3: 764.684 | S3: 106.775 | T3: 0.07 | U3: 0.263 | V3: 26.55 | W3: 99.737 | X3: 9920.229 | Y3: 16.99 | Z3: 59413400924
A4: Algeria | B4: 2002 | C4: DZA | D4: Middle East & North Africa | E4: Upper middle income | F4: 31750832 | G4: 245361000000 | H4: 27.65 | I4: 27.63 | J4: 870.213 | K4: -0.02 | L4: -0.072 | M4: 889.416 | N4: 194.839 | O4: 28012.365 | P4: 97.613 | Q4: 60.52 | R4: 824.497 | S4: 118.397 | T4: 0.06 | U4: 0.217 | V4: 27.59 | W4: 99.783 | X4: 10139.907 | Y4: 17.64 | Z4: 61516103406
A5: Algeria | B5: 2003 | C5: DZA | D5: Middle East & North Africa | E5: Upper middle income | F5: 32175813 | G5: 273569000000 | H5: 29.57 | I5: 29.58 | J5: 919.324 | K5: 0.01 | L5: 0.034 | M5: 938.576 | N5: 205.932 | O5: 29170.23 | P5: 96.787 | Q5: 61.13 | R5: 918.828 | S5: 123.174 | T5: 0.26 | U5: 0.879 | V5: 29.31 | W5: 99.121 | X5: 10471.285 | Y5: 18.75 | Z5: 73482264191
A6: Algeria | B6: 2004 | C6: DZA | D6: Middle East & North Africa | E6: Upper middle income | F6: 32628286 | G6: 296774000000 | H6: 31.25 | I6: 31.26 | J6: 958.064 | K6: 0.01 | L6: 0.032 | M6: 920.549 | N6: 211.899 | O6: 28213.23 | P6: 96.992 | Q6: 60.589 | R6: 971.698 | S6: 128.747 | T6: 0.25 | U6: 0.8 | V6: 31 | W6: 99.2 | X6: 10720.079 | Y6: 19.83 | Z6: 91913680985
A7: Algeria | B7: 2005 | C7: DZA | D7: Middle East & North Africa | E7: Upper middle income | F7: 33109258 | G7: 326854000000 | H7: 33.91 | I7: 33.99 | J7: 1026.601 | K7: 0.08 | L7: 0.235 | M7: 849.117 | N7: 223.56 | O7: 25645.924 | P7: 96.255 | Q7: 61.053 | R7: 1005.27 | S7: 134.213 | T7: 0.55 | U7: 1.622 | V7: 33.36 | W7: 98.378 | X7: 11062.512 | Y7: 21.34 | Z7: 107047000000
A8: Algeria | B8: 2006 | C8: DZA | D8: Middle East & North Africa | E8: Upper middle income | F8: 33623505 | G8: 345705000000 | H8: 35.23 | I8: 35.31 | J8: 1050.158 | K8: 0.08 | L8: 0.227 | M8: 812.995 | N8: 228.497 | O8: 24179.363 | P8: 97.247 | Q8: 60.261 | R8: 1002.529 | S8: 139.846 | T8: 0.22 | U8: 0.624 | V8: 35.01 | W8: 99.376 | X8: 11278.422 | Y8: 22.4 | Z8: 123084000000
A9: Algeria | B9: 2007 | C9: DZA | D9: Middle East & North Africa | E9: Upper middle income | F9: 34189420 | G9: 371665000000 | H9: 37.19 | I9: 37.2 | J9: 1088.056 | K9: 0.01 | L9: 0.027 | M9: 816.46 | N9: 233.807 | O9: 23880.482 | P9: 97.284 | Q9: 58.51 | R9: 1005.786 | S9: 156.39 | T9: 0.22 | U9: 0.592 | V9: 36.97 | W9: 99.408 | X9: 11688.989 | Y9: 23.65 | Z9: 142483000000
A10: Algeria | B10: 2008 | C10: DZA | D10: Middle East & North Africa | E10: Upper middle income | F10: 34816963 | G10: 395659000000 | H10: 40.23 | I10: 40.18 | J10: 1154.035 | K10: -0.05 | L10: -0.124 | M10: 826.008 | N10: 244.042 | O10: 23724.295 | P10: 97.34 | Q10: 57.624 | R10: 985.771 | S10: 169.916 | T10: 0.28 | U10: 0.696 | V10: 39.95 | W10: 99.304 | X10: 12165.246 | Y10: 25.56 | Z10: 180384000000
A11: Algeria | B11: 2009 | C11: DZA | D11: Middle East & North Africa | E11: Upper middle income | F11: 35490442 | G11: 418248000000 | H11: 38.5 | I11: 38.47 | J11: 1083.954 | K11: -0.03 | L11: -0.078 | M11: 765.669 | N11: 262.118 | O11: 21573.943 | P11: 97.636 | Q11: 58.404 | R11: 898.231 | S11: 180.134 | T11: 0.3 | U11: 0.779 | V11: 38.2 | W11: 99.221 | X11: 12647.33 | Y11: 24.43 | Z11: 150317000000
A12: Algeria | B12: 2010 | C12: DZA | D12: Middle East & North Africa | E12: Upper middle income | F12: 36188237 | G12: 450706000000 | H12: 45.73 | I12: 45.66 | J12: 1261.736 | K12: -0.07 | L12: -0.153 | M12: 773.966 | N12: 253.272 | O12: 21387.213 | P12: 97.529 | Q12: 57.698 | R12: 858.003 | S12: 181.612 | T12: 0.17 | U12: 0.372 | V12: 45.56 | W12: 99.628 | X12: 12130.873 | Y12: 29.13 | Z12: 177785000000
A13: Algeria | B13: 2011 | C13: DZA | D13: Middle East & North Africa | E13: Upper middle income | F13: 36903374 | G13: 482029000000 | H13: 51.22 | I13: 51.08 | J13: 1384.155 | K13: -0.14 | L13: -0.274 | M13: 795.987 | N13: 267.97 | O13: 21569.504 | P13: 96.935 | Q13: 57.7 | R13: 833.58 | S13: 192.228 | T13: 0.5 | U13: 0.976 | V13: 50.72 | W13: 99.024 | X13: 12586.607 | Y13: 32.44 | Z13: 218332000000
... A385: United Arab Emirates | B385: 2023 | C385: ARE | D385: Middle East & North Africa | E385: High income | F385: 10642089 | G385: 905673000000 | H385: 167.53 | I385: 167.43 | J385: 15732.812 | K385: -0.1 | L385: -0.06 | M385: 552.688 | N385: 670.1 | O385: 51934.125 | P385: 70.686 | Q385: 46.889 | R385: 2096.123 | S385: 610.676 | T385: 14.67 | U385: 8.757 | V385: 118.42 | W385: 70.686 | X385: 134679.92 | Y385: 81.05 | Z385: 522622000000

Sheet Sheet5
A3: Row Labels | B3: Sum of Renewables Share (%)
A4: 2000 | B4: 0.19448991
A5: 2001 | B5: 0.18077066
A6: 2002 | B6: 0.16467587
A7: 2003 | B7: 0.14350797
A8: Grand Total | B8: 0.68344441

Sheet Sheet6
A3: Row Labels | B3: Sum of Gas Production (TWH eq) | C3: Sum of Oil Production (TWH eq)
A4: 2000 | B4: 202.125 | C4: 452.605
A5: 2001 | B5: 242.55 | C5: 437.289
A6: 2002 | B6: 262.763 | C6: 433.108
A7: 2003 | B7: 289.713 | C7: 431.153
A8: Grand Total | B8: 997.151 | C8: 1754.155

Sheet Sheet7
A3: Row Labels | B3: Sum of Electricity Generation(TWH) | C3: Sum of Electricity Demand (TWH0
A4: 2000 | B4: 73.32 | C4: 73.17
A5: 2001 | B5: 80.71 | C5: 80.5
A6: 2002 | B6: 86.23 | C6: 85.45
A7: 2003 | B7: 92.19 | C7: 91.27
A8: Grand Total | B8: 332.45 | C8: 330.39

Sheet Sheet9
A3: Row Labels | B3: Sum of net_elec_imports
A4: 2000 | B4: -0.15
A5: 2001 | B5: -0.21
A6: 2002 | B6: -0.78
A7: 2003 | B7: -0.92
A8: 2004 | B8: -0.7
A9: 2005 | B9: -0.78
A10: 2006 | B10: -0.35
A11: 2007 | B11: -0.56
A12: 2008 | B12: -0.9
A13: 2009 | B13: -0.94
A14: 2010 | B14: -1.44
A15: 2011 | B15: -1.58
... A27: 2023 | B27: -1.39
A28: Grand Total | B28: -19.3

Sheet Egypt_KPI
A1: مؤشرات الإنتاج والاستهلاك — مصر (2000–2023)
A2: year | B2: Electricity Generation(TWH) | C2: Electricity Demand (TWH0 | D2: electricity_demand_per_capita | E2: net_elec_imports | F2: Gas Production (TWH eq) | G2: Gas Consumption (TWH eq) | H2: gas_prod_per_capita | I2: Oil Production (TWH eq) | J2: Oil Consumption (TWH eq) | K2: Renewable Elec (TWH) | L2: renewables_share_elec | M2: Fossil Elec (TWh) | N2: Renewables Share (%) | O2: energy_per_capita | P2: Gas Net Balance (TWh eq) | Q2: GDP (current US$, WB) | R2: gas_share_elec
A3: 2000 | B3: =SUMIFS(Table1[electricity_generation],Table1[country],"Egypt",Table1[year],2000) -> 73.32 | C3: =SUMIFS(Table1[electricity_demand],Table1[country],"Egypt",Table1[year],2000) -> 73.17 | D3: 1001.186 | E3: -0.15 | F3: =SUMIFS(Table1[gas_production],Table1[country],"Egypt",Table1[year],2000) -> 202.125 | G3: =SUMIFS(Table1[gas_consumption],Table1[country],"Egypt",Table1[year],2000) -> 192.5 | H3: 2765.68 | I3: =SUMIFS(Table1[oil_production],Table1[country],"Egypt",Table1[year],2000) -> 452.605 | J3: =SUMIFS(Table1[oil_consumption],Table1[country],"Egypt",Table1[year],EnergyData!B26) -> 323.759 | K3: =SUMIFS(Table1[renewables_electricity],Table1[country],"Egypt",Table1[year],EnergyData!B26) -> 14.26 | L3: 19.449 | M3: =SUMIFS(Table1[fossil_electricity],Table1[country],"Egypt",Table1[year],EnergyData!B26) -> 59.06 | N3: =IFERROR(K3/(K3+M3),0) -> 0.19448991 | O3: 7779.254 | P3: =Table3[[#This Row],[Gas Production (TWH eq)]]-Table3[[#This Row],[Gas Consumption (TWH eq)]] -> 9.625 | Q3: =SUMIFS(Table1[gdp_worldbank_usd],Table1[country],"Egypt",Table1[year],EnergyData!B26) -> 99838543960 | R3: 57.542
A4: =A3+1 -> 2001 | B4: =SUMIFS(Table1[electricity_generation],Table1[country],"Egypt",Table1[year],2001) -> 80.71 | C4: =SUMIFS(Table1[electricity_demand],Table1[country],"Egypt",Table1[year],2000 + 1) -> 80.5 | D4: 1078.336 | E4: -0.21 | F4: =SUMIFS(Table1[gas_production],Table1[country],"Egypt",Table1[year],2001) -> 242.55 | G4: =SUMIFS(Table1[gas_consumption],Table1[country],"Egypt",Table1[year],2001) -> 235.812 | H4: 3249.074 | I4: =SUMIFS(Table1[oil_production],Table1[country],"Egypt",Table1[year],2001) -> 437.289 | J4: =SUMIFS(Table1[oil_consumption],Table1[country],"Egypt",Table1[year],EnergyData!B27) -> 305.734 | K4: =SUMIFS(Table1[renewables_electricity],Table1[country],"Egypt",Table1[year],EnergyData!B27) -> 14.59 | L4: 18.077 | M4: =SUMIFS(Table1[fossil_electricity],Table1[country],"Egypt",Table1[year],EnergyData!B27) -> 66.12 | N4: =IFERROR(K4/(K4+M4),0) -> 0.18077066 | O4: 7947.725 | P4: =Table3[[#This Row],[Gas Production (TWH eq)]]-Table3[[#This Row],[Gas Consumption (TWH eq)]] -> 6.738 | Q4: =SUMIFS(Table1[gdp_worldbank_usd],Table1[country],"Egypt",Table1[year],EnergyData!B27) -> 96684636119 | R4: 60.055
A5: =A4+1 -> 2002 | B5: =SUMIFS(Table1[electricity_generation],Table1[country],"Egypt",Table1[year],2002) -> 86.23 | C5: =SUMIFS(Table1[electricity_demand],Table1[country],"Egypt",Table1[year],2002) -> 85.45 | D5: 1120.815 | E5: -0.78 | F5: =SUMIFS(Table1[gas_production],Table1[country],"Egypt",Table1[year],2002) -> 262.763 | G5: =SUMIFS(Table1[gas_consumption],Table1[country],"Egypt",Table1[year],2002) -> 255.062 | H5: 3446.557 | I5: =SUMIFS(Table1[oil_production],Table1[country],"Egypt",Table1[year],2002) -> 433.108 | J5: =SUMIFS(Table1[oil_consumption],Table1[country],"Egypt",Table1[year],EnergyData!B28) -> 304.168 | K5: =SUMIFS(Table1[renewables_electricity],Table1[country],"Egypt",Table1[year],EnergyData!B28) -> 14.2 | L5: 16.468 | M5: =SUMIFS(Table1[fossil_electricity],Table1[country],"Egypt",Table1[year],EnergyData!B28) -> 72.03 | N5: =IFERROR(K5/(K5+M5),0) -> 0.16467587 | O5: 8004.338 | P5: =Table3[[#This Row],[Gas Production (TWH eq)]]-Table3[[#This Row],[Gas Consumption (TWH eq)]] -> 7.701 | Q5: =SUMIFS(Table1[gdp_worldbank_usd],Table1[country],"Egypt",Table1[year],EnergyData!B28) -> 85146067416 | R5: 66.624
A6: =A5+1 -> 2003 | B6: =SUMIFS(Table1[electricity_generation],Table1[country],"Egypt",Table1[year],2003) -> 92.19 | C6: =SUMIFS(Table1[electricity_demand],Table1[country],"Egypt",Table1[year],2003) -> 91.27 | D6: 1172.329 | E6: -0.92 | F6: =SUMIFS(Table1[gas_production],Table1[country],"Egypt",Table1[year],2003) -> 289.713 | G6: =SUMIFS(Table1[gas_consumption],Table1[country],"Egypt",Table1[year],2003) -> 285.862 | H6: 3721.25 | I6: =SUMIFS(Table1[oil_production],Table1[country],"Egypt",Table1[year],2003) -> 431.153 | J6: =SUMIFS(Table1[oil_consumption],Table1[country],"Egypt",Table1[year],EnergyData!B29) -> 311.878 | K6: =SUMIFS(Table1[renewables_electricity],Table1[country],"Egypt",Table1[year],EnergyData!B29) -> 13.23 | L6: 14.351 | M6: =SUMIFS(Table1[fossil_electricity],Table1[country],"Egypt",Table1[year],EnergyData!B29) -> 78.96 | N6: =IFERROR(K6/(K6+M6),0) -> 0.14350797 | O6: 8297.523 | P6: =Table3[[#This Row],[Gas Production (TWH eq)]]-Table3[[#This Row],[Gas Consumption (TWH eq)]] -> 3.851 | Q6: =SUMIFS(Table1[gdp_worldbank_usd],Table1[country],"Egypt",Table1[year],EnergyData!B29) -> 80288461538 | R6: 69.444
A7: =A6+1 -> 2004 | B7: =SUMIFS(Table1[electricity_generation],Table1[country],"Egypt",Table1[year],2004) -> 98.25 | C7: =SUMIFS(Table1[electricity_demand],Table1[country],"Egypt",Table1[year],2003 + 1) -> 97.55 | D7: 1227.392 | E7: -0.7 | F7: =SUMIFS(Table1[gas_production],Table1[country],"Egypt",Table1[year],2004) -> 317.625 | G7: =SUMIFS(Table1[gas_consumption],Table1[country],"Egypt",Table1[year],2004) -> 305.112 | H7: 3996.417 | I7: =SUMIFS(Table1[oil_production],Table1[country],"Egypt",Table1[year],2004) -> 405.197 | J7: =SUMIFS(Table1[oil_consumption],Table1[country],"Egypt",Table1[year],EnergyData!B30) -> 328.398 | K7: =SUMIFS(Table1[renewables_electricity],Table1[country],"Egypt",Table1[year],EnergyData!B30) -> 13.33 | L7: 13.567 | M7: =SUMIFS(Table1[fossil_electricity],Table1[country],"Egypt",Table1[year],EnergyData!B30) -> 84.92 | N7: =IFERROR(K7/(K7+M7),0) -> 0.1356743 | O7: 8581.729 | P7: =Table3[[#This Row],[Gas Production (TWH eq)]]-Table3[[#This Row],[Gas Consumption (TWH eq)]] -> 12.513 | Q7: =SUMIFS(Table1[gdp_worldbank_usd],Table1[country],"Egypt",Table1[year],EnergyData!B30) -> 78782467532 | R7: 75.776
A8: =A7+1 -> 2005 | B8: =SUMIFS(Table1[electricity_generation],Table1[country],"Egypt",Table1[year],2005) -> 104.94 | C8: =SUMIFS(Table1[electricity_demand],Table1[country],"Egypt",Table1[year],2004 + 1) -> 104.16 | D8: 1284.324 | E8: -0.78 | F8: =SUMIFS(Table1[gas_production],Table1[country],"Egypt",Table1[year],2005) -> 409.062 | G8: =SUMIFS(Table1[gas_consumption],Table1[country],"Egypt",Table1[year],2005) -> 304.15 | H8: 5043.864 | I8: =SUMIFS(Table1[oil_production],Table1[country],"Egypt",Table1[year],2005) -> 385.736 | J8: =SUMIFS(Table1[oil_consumption],Table1[country],"Egypt",Table1[year],EnergyData!B31) -> 347.704 | K8: =SUMIFS(Table1[renewables_electricity],Table1[country],"Egypt",Table1[year],EnergyData!B31) -> 13.15 | L8: 12.531 | M8: =SUMIFS(Table1[fossil_electricity],Table1[country],"Egypt",Table1[year],EnergyData!B31) -> 91.79 | N8: =IFERROR(K8/(K8+M8),0) -> 0.1253097 | O8: 8624.019 | P8: =Table3[[#This Row],[Gas Production (TWH eq)]]-Table3[[#This Row],[Gas Consumption (TWH eq)]] -> 104.912 | Q8: =SUMIFS(Table1[gdp_worldbank_usd],Table1[country],"Egypt",Table1[year],EnergyData!B31) -> 89660339660 | R8: 73.175
A9: =A8+1 -> 2006 | B9: =SUMIFS(Table1[electricity_generation],Table1[country],"Egypt",Table1[year],2006) -> 111.66 | C9: =SUMIFS(Table1[electricity_demand],Table1[country],"Egypt",Table1[year],2005 + 1) -> 111.31 | D9: 1345.943 | E9: -0.35 | F9: =SUMIFS(Table1[gas_production],Table1[country],"Egypt",Table1[year],2006) -> 526.487 | G9: =SUMIFS(Table1[gas_consumption],Table1[country],"Egypt",Table1[year],2006) -> 351.312 | H9: 6366.202 | I9: =SUMIFS(Table1[oil_production],Table1[country],"Egypt",Table1[year],2006) -> 385.671 | J9: =SUMIFS(Table1[oil_consumption],Table1[country],"Egypt",Table1[year],EnergyData!B32) -> 337.331 | K9: =SUMIFS(Table1[renewables_electricity],Table1[country],"Egypt",Table1[year],EnergyData!B32) -> 13.39 | L9: 11.992 | M9: =SUMIFS(Table1[fossil_electricity],Table1[country],"Egypt",Table1[year],EnergyData!B32) -> 98.27 | N9: =IFERROR(K9/(K9+M9),0) -> 0.11991761 | O9: 8907.385 | P9: =Table3[[#This Row],[Gas Production (TWH eq)]]-Table3[[#This Row],[Gas Consumption (TWH eq)]] -> 175.175 | Q9: =SUMIFS(Table1[gdp_worldbank_usd],Table1[country],"Egypt",Table1[year],EnergyData!B32) -> 107426000000 | R9: 74.387
A10: =A9+1 -> 2007 | B10: =SUMIFS(Table1[electricity_generation],Table1[country],"Egypt",Table1[year],2007) -> 119.86 | C10: =SUMIFS(Table1[electricity_demand],Table1[country],"Egypt",Table1[year],2006 + 1) -> 119.3 | D10: 1415.583 | E10: -0.56 | F10: =SUMIFS(Table1[gas_production],Table1[country],"Egypt",Table1[year],2007) -> 536.016 | G10: =SUMIFS(Table1[gas_consumption],Table1[country],"Egypt",Table1[year],2007) -> 369.215 | H10: 6360.231 | I10: =SUMIFS(Table1[oil_production],Table1[country],"Egypt",Table1[year],2007) -> 393.21 | J10: =SUMIFS(Table1[oil_consumption],Table1[country],"Egypt",Table1[year],EnergyData!B33) -> 364.287 | K10: =SUMIFS(Table1[renewables_electricity],Table1[country],"Egypt",Table1[year],EnergyData!B33) -> 14.88 | L10: 12.414 | M10: =SUMIFS(Table1[fossil_electricity],Table1[country],"Egypt",Table1[year],EnergyData!B33) -> 104.98 | N10: =IFERROR(K10/(K10+M10),0) -> 0.12414484 | O10: 9309.617 | P10: =Table3[[#This Row],[Gas Production (TWH eq)]]-Table3[[#This Row],[Gas Consumption (TWH eq)]] -> 166.801 | Q10: =SUMIFS(Table1[gdp_worldbank_usd],Table1[country],"Egypt",Table1[year],EnergyData!B33) -> 130438000000 | R10: 74.428
A11: =A10+1 -> 2008 | B11: =SUMIFS(Table1[electricity_generation],Table1[country],"Egypt",Table1[year],2008) -> 128.8 | C11: =SUMIFS(Table1[electricity_demand],Table1[country],"Egypt",Table1[year],2007 + 1) -> 127.9 | D11: 1489.551 | E11: -0.9 | F11: =SUMIFS(Table1[gas_production],Table1[country],"Egypt",Table1[year],2008) -> 567.586 | G11: =SUMIFS(Table1[gas_consumption],Table1[country],"Egypt",Table1[year],2008) -> 393.085 | H11: 6610.232 | I11: =SUMIFS(Table1[oil_production],Table1[country],"Egypt",Table1[year],2008) -> 403.03 | J11: =SUMIFS(Table1[oil_consumption],Table1[country],"Egypt",Table1[year],EnergyData!B34) -> 385.617 | K11: =SUMIFS(Table1[renewables_electricity],Table1[country],"Egypt",Table1[year],EnergyData!B34) -> 16.03 | L11: 12.446 | M11: =SUMIFS(Table1[fossil_electricity],Table1[country],"Egypt",Table1[year],EnergyData!B34) -> 112.77 | N11: =IFERROR(K11/(K11+M11),0) -> 0.12445652 | O11: 9687.769 | P11: =Table3[[#This Row],[Gas Production (TWH eq)]]-Table3[[#This Row],[Gas Consumption (TWH eq)]] -> 174.501 | Q11: =SUMIFS(Table1[gdp_worldbank_usd],Table1[country],"Egypt",Table1[year],EnergyData!B34) -> 162818000000 | R11: 73.649
A12: =A11+1 -> 2009 | B12: =SUMIFS(Table1[electricity_generation],Table1[country],"Egypt",Table1[year],2009) -> 134.27 | C12: =SUMIFS(Table1[electricity_demand],Table1[country],"Egypt",Table1[year],2008 + 1) -> 133.33 | D12: 1523.743 | E12: -0.94 | F12: =SUMIFS(Table1[gas_production],Table1[country],"Egypt",Table1[year],2009) -> 603.391 | G12: =SUMIFS(Table1[gas_consumption],Table1[country],"Egypt",Table1[year],2009) -> 409.447 | H12: 6895.771 | I12: =SUMIFS(Table1[oil_production],Table1[country],"Egypt",Table1[year],2009) -> 410.074 | J12: =SUMIFS(Table1[oil_consumption],Table1[country],"Egypt",Table1[year],EnergyData!B35) -> 403.661 | K12: =SUMIFS(Table1[renewables_electricity],Table1[country],"Egypt",Table1[year],EnergyData!B35) -> 14.81 | L12: 11.03 | M12: =SUMIFS(Table1[fossil_electricity],Table1[country],"Egypt",Table1[year],EnergyData!B35) -> 119.46 | N12: =IFERROR(K12/(K12+M12),0) -> 0.11030014 | O12: 9847.488 | P12: =Table3[[#This Row],[Gas Production (TWH eq)]]-Table3[[#This Row],[Gas Consumption (TWH eq)]] -> 193.944 | Q12: =SUMIFS(Table1[gdp_worldbank_usd],Table1[country],"Egypt",Table1[year],EnergyData!B35) -> 189147000000 | R12: 73.538
A13: =A12+1 -> 2010 | B13: =SUMIFS(Table1[electricity_generation],Table1[country],"Egypt",Table1[year],2010) -> 144.43 | C13: =SUMIFS(Table1[electricity_demand],Table1[country],"Egypt",Table1[year],2009 + 1) -> 142.99 | D13: 1603.098 | E13: -1.44 | F13: =SUMIFS(Table1[gas_production],Table1[country],"Egypt",Table1[year],2010) -> 590.205 | G13: =SUMIFS(Table1[gas_consumption],Table1[country],"Egypt",Table1[year],2010) -> 434.184 | H13: 6616.939 | I13: =SUMIFS(Table1[oil_production],Table1[country],"Egypt",Table1[year],2010) -> 407.399 | J13: =SUMIFS(Table1[oil_consumption],Table1[country],"Egypt",Table1[year],EnergyData!B36) -> 415.594 | K13: =SUMIFS(Table1[renewables_electricity],Table1[country],"Egypt",Table1[year],EnergyData!B36) -> 14.39 | L13: 9.963 | M13: =SUMIFS(Table1[fossil_electricity],Table1[country],"Egypt",Table1[year],EnergyData!B36) -> 130.04 | N13: =IFERROR(K13/(K13+M13),0) -> 0.09963304 | O13: 10035.327 | P13: =Table3[[#This Row],[Gas Production (TWH eq)]]-Table3[[#This Row],[Gas Consumption (TWH eq)]] -> 156.021 | Q13: =SUMIFS(Table1[gdp_worldbank_usd],Table1[country],"Egypt",Table1[year],EnergyData!B36) -> 218984000000 | R13: 76.231
A14: =A13+1 -> 2011 | B14: =SUMIFS(Table1[electricity_generation],Table1[country],"Egypt",Table1[year],2011) -> 149.56 | C14: =SUMIFS(Table1[electricity_demand],Table1[country],"Egypt",Table1[year],2010 + 1) -> 147.98 | D14: 1624.492 | E14: -1.58 | F14: =SUMIFS(Table1[gas_production],Table1[country],"Egypt",Table1[year],2011) -> 591.433 | G14: =SUMIFS(Table1[gas_consumption],Table1[country],"Egypt",Table1[year],2011) -> 477.593 | H14: 6492.622 | I14: =SUMIFS(Table1[oil_production],Table1[country],"Egypt",Table1[year],2011) -> 402.386 | J14: =SUMIFS(Table1[oil_consumption],Table1[country],"Egypt",Table1[year],EnergyData!B37) -> 418.222 | K14: =SUMIFS(Table1[renewables_electricity],Table1[country],"Egypt",Table1[year],EnergyData!B37) -> 14.72 | L14: 9.842 | M14: =SUMIFS(Table1[fossil_electricity],Table1[country],"Egypt",Table1[year],EnergyData!B37) -> 134.84 | N14: =IFERROR(K14/(K14+M14),0) -> 0.098422038 | O14: 10336.393 | P14: =Table3[[#This Row],[Gas Production (TWH eq)]]-Table3[[#This Row],[Gas Consumption (TWH eq)]] -> 113.84 | Q14: =SUMIFS(Table1[gdp_worldbank_usd],Table1[country],"Egypt",Table1[year],EnergyData!B37) -> 235990000000 | R14: 78.537
A15: =A14+1 -> 2012 | B15: =SUMIFS(Table1[electricity_generation],Table1[country],"Egypt",Table1[year],2012) -> 162.84 | C15: =SUMIFS(Table1[electricity_demand],Table1[country],"Egypt",Table1[year],2011 + 1) -> 162.44 | D15: 1743.648 | E15: -0.4 | F15: =SUMIFS(Table1[gas_production],Table1[country],"Egypt",Table1[year],2012) -> 585.982 | G15: =SUMIFS(Table1[gas_consumption],Table1[country],"Egypt",Table1[year],2012) -> 506.371 | H15: 6289.991 | I15: =SUMIFS(Table1[oil_production],Table1[country],"Egypt",Table1[year],2012) -> 403.864 | J15: =SUMIFS(Table1[oil_consumption],Table1[country],"Egypt",Table1[year],EnergyData!B38) -> 428.225 | K15: =SUMIFS(Table1[renewables_electricity],Table1[country],"Egypt",Table1[year],EnergyData!B38) -> 14.87 | L15: 9.132 | M15: =SUMIFS(Table1[fossil_electricity],Table1[country],"Egypt",Table1[year],EnergyData!B38) -> 147.97 | N15: =IFERROR(K15/(K15+M15),0) -> 0.09131663 | O15: 10518.4 | P15: =Table3[[#This Row],[Gas Production (TWH eq)]]-Table3[[#This Row],[Gas Consumption (TWH eq)]] -> 79.611 | Q15: =SUMIFS(Table1[gdp_worldbank_usd],Table1[country],"Egypt",Table1[year],EnergyData!B38) -> 279117000000 | R15: 77.72
A16: =A15+1 -> 2013 | B16: =SUMIFS(Table1[electricity_generation],Table1[country],"Egypt",Table1[year],2013) -> 165.08 | C16: =SUMIFS(Table1[electricity_demand],Table1[country],"Egypt",Table1[year],2012 + 1) -> 164.68 | D16: 1727.409 | E16: -0.4 | F16: =SUMIFS(Table1[gas_production],Table1[country],"Egypt",Table1[year],2013) -> 539.648 | G16: =SUMIFS(Table1[gas_consumption],Table1[country],"Egypt",Table1[year],2013) -> 495.014 | H16: 5660.634 | I16: =SUMIFS(Table1[oil_production],Table1[country],"Egypt",Table1[year],2013) -> 399.619 | J16: =SUMIFS(Table1[oil_consumption],Table1[country],"Egypt",Table1[year],EnergyData!B39) -> 433.327 | K16: =SUMIFS(Table1[renewables_electricity],Table1[country],"Egypt",Table1[year],EnergyData!B39) -> 14.85 | L16: 8.996 | M16: =SUMIFS(Table1[fossil_electricity],Table1[country],"Egypt",Table1[year],EnergyData!B39) -> 150.23 | N16: =IFERROR(K16/(K16+M16),0) -> 0.089956385 | O16: 10209.089 | P16: =Table3[[#This Row],[Gas Production (TWH eq)]]-Table3[[#This Row],[Gas Consumption (TWH eq)]] -> 44.634 | Q16: =SUMIFS(Table1[gdp_worldbank_usd],Table1[country],"Egypt",Table1[year],EnergyData!B39) -> 288434000000 | R16: 74.612
A17: =A16+1 -> 2014 | B17: =SUMIFS(Table1[electricity_generation],Table1[country],"Egypt",Table1[year],2014) -> 171.24 | C17: =SUMIFS(Table1[electricity_demand],Table1[country],"Egypt",Table1[year],2013 + 1) -> 170.56 | D17: 1748.819 | E17: -0.68 | F17: =SUMIFS(Table1[gas_production],Table1[country],"Egypt",Table1[year],2014) -> 469.611 | G17: =SUMIFS(Table1[gas_consumption],Table1[country],"Egypt",Table1[year],2014) -> 462.188 | H17: 4815.103 | I17: =SUMIFS(Table1[oil_production],Table1[country],"Egypt",Table1[year],2014) -> 408.681 | J17: =SUMIFS(Table1[oil_consumption],Table1[country],"Egypt",Table1[year],EnergyData!B40) -> 455.288 | K17: =SUMIFS(Table1[renewables_electricity],Table1[country],"Egypt",Table1[year],EnergyData!B40) -> 14.76 | L17: 8.619 | M17: =SUMIFS(Table1[fossil_electricity],Table1[country],"Egypt",Table1[year],EnergyData!B40) -> 156.48 | N17: =IFERROR(K17/(K17+M17),0) -> 0.086194814 | O17: 9863.477 | P17: =Table3[[#This Row],[Gas Production (TWH eq)]]-Table3[[#This Row],[Gas Consumption (TWH eq)]] -> 7.423 | Q17: =SUMIFS(Table1[gdp_worldbank_usd],Table1[country],"Egypt",Table1[year],EnergyData!B40) -> 305595000000 | R17: 72.787
A18: =A17+1 -> 2015 | B18: =SUMIFS(Table1[electricity_generation],Table1[country],"Egypt",Table1[year],2015) -> 181.83 | C18: =SUMIFS(Table1[electricity_demand],Table1[country],"Egypt",Table1[year],2014 + 1) -> 181.14 | D18: 1818.723 | E18: -0.69 | F18: =SUMIFS(Table1[gas_production],Table1[country],"Egypt",Table1[year],2015) -> 425.906 | G18: =SUMIFS(Table1[gas_consumption],Table1[country],"Egypt",Table1[year],2015) -> 460.188 | H18: 4276.282 | I18: =SUMIFS(Table1[oil_production],Table1[country],"Egypt",Table1[year],2015) -> 412.063 | J18: =SUMIFS(Table1[oil_consumption],Table1[country],"Egypt",Table1[year],EnergyData!B41) -> 464.537 | K18: =SUMIFS(Table1[renewables_electricity],Table1[country],"Egypt",Table1[year],EnergyData!B41) -> 15.61 | L18: 8.585 | M18: =SUMIFS(Table1[fossil_electricity],Table1[country],"Egypt",Table1[year],EnergyData!B41) -> 166.22 | N18: =IFERROR(K18/(K18+M18),0) -> 0.08584942 | O18: 9800.544 | P18: =Table3[[#This Row],[Gas Production (TWH eq)]]-Table3[[#This Row],[Gas Consumption (TWH eq)]] -> -34.282 | Q18: =SUMIFS(Table1[gdp_worldbank_usd],Table1[country],"Egypt",Table1[year],EnergyData!B41) -> 329367000000 | R18: 71.391
A19: =A18+1 -> 2016 | B19: =SUMIFS(Table1[electricity_generation],Table1[country],"Egypt",Table1[year],2016) -> 188.19 | C19: =SUMIFS(Table1[electricity_demand],Table1[country],"Egypt",Table1[year],2015 + 1) -> 187.92 | D19: 1848.795 | E19: -0.27 | F19: =SUMIFS(Table1[gas_production],Table1[country],"Egypt",Table1[year],2016) -> 402.517 | G19: =SUMIFS(Table1[gas_consumption],Table1[country],"Egypt",Table1[year],2016) -> 493.541 | H19: 3960.049 | I19: =SUMIFS(Table1[oil_production],Table1[country],"Egypt",Table1[year],2016) -> 393.501 | J19: =SUMIFS(Table1[oil_consumption],Table1[country],"Egypt",Table1[year],EnergyData!B42) -> 480.178 | K19: =SUMIFS(Table1[renewables_electricity],Table1[country],"Egypt",Table1[year],EnergyData!B42) -> 15.83 | L19: 8.412 | M19: =SUMIFS(Table1[fossil_electricity],Table1[country],"Egypt",Table1[year],EnergyData!B42) -> 172.36 | N19: =IFERROR(K19/(K19+M19),0) -> 0.084117116 | O19: 10135.914 | P19: =Table3[[#This Row],[Gas Production (TWH eq)]]-Table3[[#This Row],[Gas Consumption (TWH eq)]] -> -91.024 | Q19: =SUMIFS(Table1[gdp_worldbank_usd],Table1[country],"Egypt",Table1[year],EnergyData!B42) -> 332442000000 | R19: 73.58
A20: =A19+1 -> 2017 | B20: =SUMIFS(Table1[electricity_generation],Table1[country],"Egypt",Table1[year],2017) -> 193.21 | C20: =SUMIFS(Table1[electricity_demand],Table1[country],"Egypt",Table1[year],2016 + 1) -> 192.87 | D20: 1859.955 | E20: -0.34 | F20: =SUMIFS(Table1[gas_production],Table1[country],"Egypt",Table1[year],2017) -> 488.113 | G20: =SUMIFS(Table1[gas_consumption],Table1[country],"Egypt",Table1[year],2017) -> 559.328 | H20: 4707.148 | I20: =SUMIFS(Table1[oil_production],Table1[country],"Egypt",Table1[year],2017) -> 374.23 | J20: =SUMIFS(Table1[oil_consumption],Table1[country],"Egypt",Table1[year],EnergyData!B43) -> 456.216 | K20: =SUMIFS(Table1[renewables_electricity],Table1[country],"Egypt",Table1[year],EnergyData!B43) -> 15.5 | L20: 8.022 | M20: =SUMIFS(Table1[fossil_electricity],Table1[country],"Egypt",Table1[year],EnergyData!B43) -> 177.71 | N20: =IFERROR(K20/(K20+M20),0) -> 0.080223591 | O20: 10325.806 | P20: =Table3[[#This Row],[Gas Production (TWH eq)]]-Table3[[#This Row],[Gas Consumption (TWH eq)]] -> -71.215 | Q20: =SUMIFS(Table1[gdp_worldbank_usd],Table1[country],"Egypt",Table1[year],EnergyData!B43) -> 248363000000 | R20: 78.635
A21: =A20+1 -> 2018 | B21: =SUMIFS(Table1[electricity_generation],Table1[country],"Egypt",Table1[year],2018) -> 199.39 | C21: =SUMIFS(Table1[electricity_demand],Table1[country],"Egypt",Table1[year],2017 + 1) -> 198.82 | D21: 1881.303 | E21: -0.57 | F21: =SUMIFS(Table1[gas_production],Table1[country],"Egypt",Table1[year],2018) -> 585.59 | G21: =SUMIFS(Table1[gas_consumption],Table1[country],"Egypt",Table1[year],2018) -> 595.953 | H21: 5541.053 | I21: =SUMIFS(Table1[oil_production],Table1[country],"Egypt",Table1[year],2018) -> 381.976 | J21: =SUMIFS(Table1[oil_consumption],Table1[country],"Egypt",Table1[year],EnergyData!B44) -> 406.445 | K21: =SUMIFS(Table1[renewables_electricity],Table1[country],"Egypt",Table1[year],EnergyData!B44) -> 16.46 | L21: 8.255 | M21: =SUMIFS(Table1[fossil_electricity],Table1[country],"Egypt",Table1[year],EnergyData!B44) -> 182.93 | N21: =IFERROR(K21/(K21+M21),0) -> 0.082551783 | O21: 10137.438 | P21: =Table3[[#This Row],[Gas Production (TWH eq)]]-Table3[[#This Row],[Gas Consumption (TWH eq)]] -> -10.363 | Q21: =SUMIFS(Table1[gdp_worldbank_usd],Table1[country],"Egypt",Table1[year],EnergyData!B44) -> 262589000000 | R21: 83.846
A22: =A21+1 -> 2019 | B22: =SUMIFS(Table1[electricity_generation],Table1[country],"Egypt",Table1[year],2019) -> 200.57 | C22: =SUMIFS(Table1[electricity_demand],Table1[country],"Egypt",Table1[year],2018 + 1) -> 199.78 | D22: 1857.5 | E22: -0.79 | F22: =SUMIFS(Table1[gas_production],Table1[country],"Egypt",Table1[year],2019) -> 649.388 | G22: =SUMIFS(Table1[gas_consumption],Table1[country],"Egypt",Table1[year],2019) -> 590.387 | H22: 6037.828 | I22: =SUMIFS(Table1[oil_production],Table1[country],"Egypt",Table1[year],2019) -> 369.974 | J22: =SUMIFS(Table1[oil_consumption],Table1[country],"Egypt",Table1[year],EnergyData!B45) -> 383.614 | K22: =SUMIFS(Table1[renewables_electricity],Table1[country],"Egypt",Table1[year],EnergyData!B45) -> 19.59 | L22: 9.767 | M22: =SUMIFS(Table1[fossil_electricity],Table1[country],"Egypt",Table1[year],EnergyData!B45) -> 180.98 | N22: =IFERROR(K22/(K22+M22),0) -> 0.097671636 | O22: 9749.406 | P22: =Table3[[#This Row],[Gas Production (TWH eq)]]-Table3[[#This Row],[Gas Consumption (TWH eq)]] -> 59.001 | Q22: =SUMIFS(Table1[gdp_worldbank_usd],Table1[country],"Egypt",Table1[year],EnergyData!B45) -> 318679000000 | R22: 85.666
A23: =A22+1 -> 2020 | B23: =SUMIFS(Table1[electricity_generation],Table1[country],"Egypt",Table1[year],2020) -> 198.6 | C23: =SUMIFS(Table1[electricity_demand],Table1[country],"Egypt",Table1[year],2019 + 1) -> 197.18 | D23: 1803.776 | E23: -1.42 | F23: =SUMIFS(Table1[gas_production],Table1[country],"Egypt",Table1[year],2020) -> 584.652 | G23: =SUMIFS(Table1[gas_consumption],Table1[country],"Egypt",Table1[year],2020) -> 583.079 | H23: 5348.315 | I23: =SUMIFS(Table1[oil_production],Table1[country],"Egypt",Table1[year],2020) -> 361.302 | J23: =SUMIFS(Table1[oil_consumption],Table1[country],"Egypt",Table1[year],EnergyData!B46) -> 332.68 | K23: =SUMIFS(Table1[renewables_electricity],Table1[country],"Egypt",Table1[year],EnergyData!B46) -> 23.76 | L23: 11.964 | M23: =SUMIFS(Table1[fossil_electricity],Table1[country],"Egypt",Table1[year],EnergyData!B46) -> 174.84 | N23: =IFERROR(K23/(K23+M23),0) -> 0.11963746 | O23: 9028.072 | P23: =Table3[[#This Row],[Gas Production (TWH eq)]]-Table3[[#This Row],[Gas Consumption (TWH eq)]] -> 1.573 | Q23: =SUMIFS(Table1[gdp_worldbank_usd],Table1[country],"Egypt",Table1[year],EnergyData!B46) -> 383818000000 | R23: 84.018
A24: =A23+1 -> 2021 | B24: =SUMIFS(Table1[electricity_generation],Table1[country],"Egypt",Table1[year],2021) -> 209.66 | C24: =SUMIFS(Table1[electricity_demand],Table1[country],"Egypt",Table1[year],2020 + 1) -> 208.19 | D24: 1876.312 | E24: -1.47 | F24: =SUMIFS(Table1[gas_production],Table1[country],"Egypt",Table1[year],2021) -> 677.994 | G24: =SUMIFS(Table1[gas_consumption],Table1[country],"Egypt",Table1[year],2021) -> 621.248 | H24: 6110.424 | I24: =SUMIFS(Table1[oil_production],Table1[country],"Egypt",Table1[year],2021) -> 344.264 | J24: =SUMIFS(Table1[oil_consumption],Table1[country],"Egypt",Table1[year],EnergyData!B47) -> 359.567 | K24: =SUMIFS(Table1[renewables_electricity],Table1[country],"Egypt",Table1[year],EnergyData!B47) -> 25.36 | L24: 12.096 | M24: =SUMIFS(Table1[fossil_electricity],Table1[country],"Egypt",Table1[year],EnergyData!B47) -> 184.3 | N24: =IFERROR(K24/(K24+M24),0) -> 0.12095774 | O24: 9564.884 | P24: =Table3[[#This Row],[Gas Production (TWH eq)]]-Table3[[#This Row],[Gas Consumption (TWH eq)]] -> 56.746 | Q24: =SUMIFS(Table1[gdp_worldbank_usd],Table1[country],"Egypt",Table1[year],EnergyData!B47) -> 424672000000 | R24: 85.591
A25: =A24+1 -> 2022 | B25: =SUMIFS(Table1[electricity_generation],Table1[country],"Egypt",Table1[year],2022) -> 216.72 | C25: =SUMIFS(Table1[electricity_demand],Table1[country],"Egypt",Table1[year],2021 + 1) -> 215.15 | D25: 1910.436 | E25: -1.57 | F25: =SUMIFS(Table1[gas_production],Table1[country],"Egypt",Table1[year],2022) -> 644.882 | G25: =SUMIFS(Table1[gas_consumption],Table1[country],"Egypt",Table1[year],2022) -> 605.909 | H25: 5726.264 | I25: =SUMIFS(Table1[oil_production],Table1[country],"Egypt",Table1[year],2022) -> 349.393 | J25: =SUMIFS(Table1[oil_consumption],Table1[country],"Egypt",Table1[year],EnergyData!B48) -> 425.229 | K25: =SUMIFS(Table1[renewables_electricity],Table1[country],"Egypt",Table1[year],EnergyData!B48) -> 25.61 | L25: 11.817 | M25: =SUMIFS(Table1[fossil_electricity],Table1[country],"Egypt",Table1[year],EnergyData!B48) -> 191.11 | N25: =IFERROR(K25/(K25+M25),0) -> 0.11817091 | O25: 9857.579 | P25: =Table3[[#This Row],[Gas Production (TWH eq)]]-Table3[[#This Row],[Gas Consumption (TWH eq)]] -> 38.973 | Q25: =SUMIFS(Table1[gdp_worldbank_usd],Table1[country],"Egypt",Table1[year],EnergyData!B48) -> 476748000000 | R25: 84.473
A26: =A25+1 -> 2023 | B26: =SUMIFS(Table1[electricity_generation],Table1[country],"Egypt",Table1[year],2023) -> 221.92 | C26: =SUMIFS(Table1[electricity_demand],Table1[country],"Egypt",Table1[year],2022 + 1) -> 220.53 | D26: 1925.425 | E26: -1.39 | F26: =SUMIFS(Table1[gas_production],Table1[country],"Egypt",Table1[year],2023) -> 571.004 | G26: =SUMIFS(Table1[gas_consumption],Table1[country],"Egypt",Table1[year],2023) -> 600.39 | H26: 4985.377 | I26: =SUMIFS(Table1[oil_production],Table1[country],"Egypt",Table1[year],2023) -> 345.46 | J26: =SUMIFS(Table1[oil_consumption],Table1[country],"Egypt",Table1[year],EnergyData!B49) -> 414.18 | K26: =SUMIFS(Table1[renewables_electricity],Table1[country],"Egypt",Table1[year],EnergyData!B49) -> 25.97 | L26: 11.702 | M26: =SUMIFS(Table1[fossil_electricity],Table1[country],"Egypt",Table1[year],EnergyData!B49) -> 195.95 | N26: =IFERROR(K26/(K26+M26),0) -> 0.11702415 | O26: 9566.154 | P26: =Table3[[#This Row],[Gas Production (TWH eq)]]-Table3[[#This Row],[Gas Consumption (TWH eq)]] -> -29.386 | Q26: =SUMIFS(Table1[gdp_worldbank_usd],Table1[country],"Egypt",Table1[year],EnergyData!B49) -> 395926000000 | R26: 80.826
B30: أحدث سنة متاحة: 2023 | C30: Column1
B31: إجمالي توليد الكهرباء (TWh) | C31: =SUMIFS(Table1[electricity_generation],Table1[country],"Egypt",Table1[year],EnergyData!B49) -> 221.92
B32: إجمالي الطلب على الكهرباء (TWh) | C32: =SUMIFS(Table1[electricity_demand],Table1[country],"Egypt",Table1[year],EnergyData!B49) -> 220.53
B33: نسبة الطاقة المتجددة (%) | C33: =SUMIFS(Table1[renewables_share_elec],Table1[country],"Egypt",Table1[year],2023)/100 -> 0.11702
B34: صافي واردات الكهرباء (TWh) | C34: =SUMIFS(Table1[net_elec_imports],Table1[country],"Egypt",Table1[year],2023) -> -1.39

Sheet ELC Prod. , Demand
A3: Row Labels | B3: Sum of Electricity Generation(TWH) | C3: Sum of Electricity Demand (TWH0
A4: 2000 | B4: 73.32 | C4: 73.17
A5: 2001 | B5: 80.71 | C5: 80.5
A6: 2002 | B6: 86.23 | C6: 85.45
A7: 2003 | B7: 92.19 | C7: 91.27
A8: Grand Total | B8: 332.45 | C8: 330.39

Sheet Gas Prod. , Con.
A3: Row Labels | B3: Sum of Gas Production (TWH eq) | C3: Sum of Gas Consumption (TWH eq)
A4: 2000 | B4: 202.125 | C4: 192.5
A5: 2001 | B5: 242.55 | C5: 235.812
A6: 2002 | B6: 262.763 | C6: 255.062
A7: 2003 | B7: 289.713 | C7: 285.862
A8: Grand Total | B8: 997.151 | C8: 969.236

Sheet Oil Prod. , Con.
A3: Row Labels | B3: Sum of Oil Production (TWH eq) | C3: Sum of Oil Consumption (TWH eq)
A4: 2000 | B4: 452.605 | C4: 323.759
A5: 2001 | B5: 437.289 | C5: 305.734
A6: 2002 | B6: 433.108 | C6: 304.168
A7: 2003 | B7: 431.153 | C7: 311.878
A8: Grand Total | B8: 1754.155 | C8: 1245.539

Sheet Sheet12
A1: year | B1: All
A2: country | B2: All
A4: Row Labels | B4: Sum of Net Elec Imports (TWh)
A5: Algeria | B5: -2.44
A6: Egypt | B6: -1.39
A7: Ethiopia | B7: -1.78
A8: Iran | B8: -6.73
A9: Iraq | B9: 6.82
A10: Israel | B10: -6.93
A11: Jordan | B11: 0.07
A12: Libya | B12: 0
A13: Morocco | B13: 1.85
A14: Nigeria | B14: -2.32
A15: Saudi Arabia | B15: -0.04
A16: South Africa | B16: -0.55
... A21: Grand Total | B21: -6.37

Sheet Trade_Analysis
A1: Year | B1: Net Elec Imports (TWh) | C1: Net Elec Imports Share of Demand (%) | D1: Gas Net Balance (Prod-Cons, TWh eq) | E1: Oil Net Balance (Prod-Cons, TWh eq)
A2: 2000 | B2: =SUMIFS(Table1[net_elec_imports],Table1[country],"Egypt",Table1[year],EnergyData!B26) -> -0.15 | C2: =SUMIFS(Table1[net_elec_imports_share_demand],Table1[country],"Egypt",Table1[year],EnergyData!B26)/100 -> -0.00205 | D2: =SUMIFS(Table1[gas_production],Table1[country],"Egypt",Table1[year],EnergyData!B26)-SUMIFS(Table1[gas_consumption],Table1[country],"Egypt",Table1[year],EnergyData!B26) -> 9.625 | E2: =SUMIFS(Table1[oil_production],Table1[country],"Egypt",Table1[year],EnergyData!B26)-SUMIFS(Table1[oil_consumption],Table1[country],"Egypt",Table1[year],EnergyData!B26) -> 128.846
A3: 2001 | B3: =SUMIFS(Table1[net_elec_imports],Table1[country],"Egypt",Table1[year],EnergyData!B27) -> -0.21 | C3: =SUMIFS(Table1[net_elec_imports_share_demand],Table1[country],"Egypt",Table1[year],EnergyData!B27)/100 -> -0.00261 | D3: =SUMIFS(Table1[gas_production],Table1[country],"Egypt",Table1[year],EnergyData!B27)-SUMIFS(Table1[gas_consumption],Table1[country],"Egypt",Table1[year],EnergyData!B27) -> 6.738 | E3: =SUMIFS(Table1[oil_production],Table1[country],"Egypt",Table1[year],EnergyData!B27)-SUMIFS(Table1[oil_consumption],Table1[country],"Egypt",Table1[year],EnergyData!B27) -> 131.555
A4: 2002 | B4: =SUMIFS(Table1[net_elec_imports],Table1[country],"Egypt",Table1[year],EnergyData!B28) -> -0.78 | C4: =SUMIFS(Table1[net_elec_imports_share_demand],Table1[country],"Egypt",Table1[year],EnergyData!B28)/100 -> -0.00913 | D4: =SUMIFS(Table1[gas_production],Table1[country],"Egypt",Table1[year],EnergyData!B28)-SUMIFS(Table1[gas_consumption],Table1[country],"Egypt",Table1[year],EnergyData!B28) -> 7.701 | E4: =SUMIFS(Table1[oil_production],Table1[country],"Egypt",Table1[year],EnergyData!B28)-SUMIFS(Table1[oil_consumption],Table1[country],"Egypt",Table1[year],EnergyData!B28) -> 128.94
A5: 2003 | B5: =SUMIFS(Table1[net_elec_imports],Table1[country],"Egypt",Table1[year],EnergyData!B29) -> -0.92 | C5: =SUMIFS(Table1[net_elec_imports_share_demand],Table1[country],"Egypt",Table1[year],EnergyData!B29)/100 -> -0.01008 | D5: =SUMIFS(Table1[gas_production],Table1[country],"Egypt",Table1[year],EnergyData!B29)-SUMIFS(Table1[gas_consumption],Table1[country],"Egypt",Table1[year],EnergyData!B29) -> 3.851 | E5: =SUMIFS(Table1[oil_production],Table1[country],"Egypt",Table1[year],EnergyData!B29)-SUMIFS(Table1[oil_consumption],Table1[country],"Egypt",Table1[year],EnergyData!B29) -> 119.275
A6: 2004 | B6: =SUMIFS(Table1[net_elec_imports],Table1[country],"Egypt",Table1[year],EnergyData!B30) -> -0.7 | C6: =SUMIFS(Table1[net_elec_imports_share_demand],Table1[country],"Egypt",Table1[year],EnergyData!B30)/100 -> -0.00718 | D6: =SUMIFS(Table1[gas_production],Table1[country],"Egypt",Table1[year],EnergyData!B30)-SUMIFS(Table1[gas_consumption],Table1[country],"Egypt",Table1[year],EnergyData!B30) -> 12.513 | E6: =SUMIFS(Table1[oil_production],Table1[country],"Egypt",Table1[year],EnergyData!B30)-SUMIFS(Table1[oil_consumption],Table1[country],"Egypt",Table1[year],EnergyData!B30) -> 76.799
A7: 2005 | B7: =SUMIFS(Table1[net_elec_imports],Table1[country],"Egypt",Table1[year],EnergyData!B31) -> -0.78 | C7: =SUMIFS(Table1[net_elec_imports_share_demand],Table1[country],"Egypt",Table1[year],EnergyData!B31)/100 -> -0.00749 | D7: =SUMIFS(Table1[gas_production],Table1[country],"Egypt",Table1[year],EnergyData!B31)-SUMIFS(Table1[gas_consumption],Table1[country],"Egypt",Table1[year],EnergyData!B31) -> 104.912 | E7: =SUMIFS(Table1[oil_production],Table1[country],"Egypt",Table1[year],EnergyData!B31)-SUMIFS(Table1[oil_consumption],Table1[country],"Egypt",Table1[year],EnergyData!B31) -> 38.032
A8: 2006 | B8: =SUMIFS(Table1[net_elec_imports],Table1[country],"Egypt",Table1[year],EnergyData!B32) -> -0.35 | C8: =SUMIFS(Table1[net_elec_imports_share_demand],Table1[country],"Egypt",Table1[year],EnergyData!B32)/100 -> -0.00314 | D8: =SUMIFS(Table1[gas_production],Table1[country],"Egypt",Table1[year],EnergyData!B32)-SUMIFS(Table1[gas_consumption],Table1[country],"Egypt",Table1[year],EnergyData!B32) -> 175.175 | E8: =SUMIFS(Table1[oil_production],Table1[country],"Egypt",Table1[year],EnergyData!B32)-SUMIFS(Table1[oil_consumption],Table1[country],"Egypt",Table1[year],EnergyData!B32) -> 48.34 | M8: Row Labels | N8: Sum of Gas Net Balance (Prod-Cons, TWh eq) | O8: Sum of Oil Net Balance (Prod-Cons, TWh eq)
A9: 2007 | B9: =SUMIFS(Table1[net_elec_imports],Table1[country],"Egypt",Table1[year],EnergyData!B33) -> -0.56 | C9: =SUMIFS(Table1[net_elec_imports_share_demand],Table1[country],"Egypt",Table1[year],EnergyData!B33)/100 -> -0.00469 | D9: =SUMIFS(Table1[gas_production],Table1[country],"Egypt",Table1[year],EnergyData!B33)-SUMIFS(Table1[gas_consumption],Table1[country],"Egypt",Table1[year],EnergyData!B33) -> 166.801 | E9: =SUMIFS(Table1[oil_production],Table1[country],"Egypt",Table1[year],EnergyData!B33)-SUMIFS(Table1[oil_consumption],Table1[country],"Egypt",Table1[year],EnergyData!B33) -> 28.923 | M9: 2000 | N9: 9.625 | O9: 128.846
A10: 2008 | B10: =SUMIFS(Table1[net_elec_imports],Table1[country],"Egypt",Table1[year],EnergyData!B34) -> -0.9 | C10: =SUMIFS(Table1[net_elec_imports_share_demand],Table1[country],"Egypt",Table1[year],EnergyData!B34)/100 -> -0.00704 | D10: =SUMIFS(Table1[gas_production],Table1[country],"Egypt",Table1[year],EnergyData!B34)-SUMIFS(Table1[gas_consumption],Table1[country],"Egypt",Table1[year],EnergyData!B34) -> 174.501 | E10: =SUMIFS(Table1[oil_production],Table1[country],"Egypt",Table1[year],EnergyData!B34)-SUMIFS(Table1[oil_consumption],Table1[country],"Egypt",Table1[year],EnergyData!B34) -> 17.413 | M10: 2001 | N10: 6.738 | O10: 131.555
A11: 2009 | B11: =SUMIFS(Table1[net_elec_imports],Table1[country],"Egypt",Table1[year],EnergyData!B35) -> -0.94 | C11: =SUMIFS(Table1[net_elec_imports_share_demand],Table1[country],"Egypt",Table1[year],EnergyData!B35)/100 -> -0.00705 | D11: =SUMIFS(Table1[gas_production],Table1[country],"Egypt",Table1[year],EnergyData!B35)-SUMIFS(Table1[gas_consumption],Table1[country],"Egypt",Table1[year],EnergyData!B35) -> 193.944 | E11: =SUMIFS(Table1[oil_production],Table1[country],"Egypt",Table1[year],EnergyData!B35)-SUMIFS(Table1[oil_consumption],Table1[country],"Egypt",Table1[year],EnergyData!B35) -> 6.413 | M11: 2002 | N11: 7.701 | O11: 128.94
A12: 2010 | B12: =SUMIFS(Table1[net_elec_imports],Table1[country],"Egypt",Table1[year],EnergyData!B36) -> -1.44 | C12: =SUMIFS(Table1[net_elec_imports_share_demand],Table1[country],"Egypt",Table1[year],EnergyData!B36)/100 -> -0.01007 | D12: =SUMIFS(Table1[gas_production],Table1[country],"Egypt",Table1[year],EnergyData!B36)-SUMIFS(Table1[gas_consumption],Table1[country],"Egypt",Table1[year],EnergyData!B36) -> 156.021 | E12: =SUMIFS(Table1[oil_production],Table1[country],"Egypt",Table1[year],EnergyData!B36)-SUMIFS(Table1[oil_consumption],Table1[country],"Egypt",Table1[year],EnergyData!B36) -> -8.195 | M12: 2003 | N12: 3.851 | O12: 119.275
A13: 2011 | B13: =SUMIFS(Table1[net_elec_imports],Table1[country],"Egypt",Table1[year],EnergyData!B37) -> -1.58 | C13: =SUMIFS(Table1[net_elec_imports_share_demand],Table1[country],"Egypt",Table1[year],EnergyData!B37)/100 -> -0.01068 | D13: =SUMIFS(Table1[gas_production],Table1[country],"Egypt",Table1[year],EnergyData!B37)-SUMIFS(Table1[gas_consumption],Table1[country],"Egypt",Table1[year],EnergyData!B37) -> 113.84 | E13: =SUMIFS(Table1[oil_production],Table1[country],"Egypt",Table1[year],EnergyData!B37)-SUMIFS(Table1[oil_consumption],Table1[country],"Egypt",Table1[year],EnergyData!B37) -> -15.836 | M13: 2004 | N13: 12.513 | O13: 76.799
A14: 2012 | B14: =SUMIFS(Table1[net_elec_imports],Table1[country],"Egypt",Table1[year],EnergyData!B38) -> -0.4 | C14: =SUMIFS(Table1[net_elec_imports_share_demand],Table1[country],"Egypt",Table1[year],EnergyData!B38)/100 -> -0.00246 | D14: =SUMIFS(Table1[gas_production],Table1[country],"Egypt",Table1[year],EnergyData!B38)-SUMIFS(Table1[gas_consumption],Table1[country],"Egypt",Table1[year],EnergyData!B38) -> 79.611 | E14: =SUMIFS(Table1[oil_production],Table1[country],"Egypt",Table1[year],EnergyData!B38)-SUMIFS(Table1[oil_consumption],Table1[country],"Egypt",Table1[year],EnergyData!B38) -> -24.361 | M14: 2005 | N14: 104.912 | O14: 38.032
A15: 2013 | B15: =SUMIFS(Table1[net_elec_imports],Table1[country],"Egypt",Table1[year],EnergyData!B39) -> -0.4 | C15: =SUMIFS(Table1[net_elec_imports_share_demand],Table1[country],"Egypt",Table1[year],EnergyData!B39)/100 -> -0.00243 | D15: =SUMIFS(Table1[gas_production],Table1[country],"Egypt",Table1[year],EnergyData!B39)-SUMIFS(Table1[gas_consumption],Table1[country],"Egypt",Table1[year],EnergyData!B39) -> 44.634 | E15: =SUMIFS(Table1[oil_production],Table1[country],"Egypt",Table1[year],EnergyData!B39)-SUMIFS(Table1[oil_consumption],Table1[country],"Egypt",Table1[year],EnergyData!B39) -> -33.708 | M15: 2006 | N15: 175.175 | O15: 48.34
A16: 2014 | B16: =SUMIFS(Table1[net_elec_imports],Table1[country],"Egypt",Table1[year],EnergyData!B40) -> -0.68 | C16: =SUMIFS(Table1[net_elec_imports_share_demand],Table1[country],"Egypt",Table1[year],EnergyData!B40)/100 -> -0.00399 | D16: =SUMIFS(Table1[gas_production],Table1[country],"Egypt",Table1[year],EnergyData!B40)-SUMIFS(Table1[gas_consumption],Table1[country],"Egypt",Table1[year],EnergyData!B40) -> 7.423 | E16: =SUMIFS(Table1[oil_production],Table1[country],"Egypt",Table1[year],EnergyData!B40)-SUMIFS(Table1[oil_consumption],Table1[country],"Egypt",Table1[year],EnergyData!B40) -> -46.607 | M16: 2007 | N16: 166.801 | O16: 28.923
A17: 2015 | B17: =SUMIFS(Table1[net_elec_imports],Table1[country],"Egypt",Table1[year],EnergyData!B41) -> -0.69 | C17: =SUMIFS(Table1[net_elec_imports_share_demand],Table1[country],"Egypt",Table1[year],EnergyData!B41)/100 -> -0.00381 | D17: =SUMIFS(Table1[gas_production],Table1[country],"Egypt",Table1[year],EnergyData!B41)-SUMIFS(Table1[gas_consumption],Table1[country],"Egypt",Table1[year],EnergyData!B41) -> -34.282 | E17: =SUMIFS(Table1[oil_production],Table1[country],"Egypt",Table1[year],EnergyData!B41)-SUMIFS(Table1[oil_consumption],Table1[country],"Egypt",Table1[year],EnergyData!B41) -> -52.474 | M17: 2008 | N17: 174.501 | O17: 17.413
A18: 2016 | B18: =SUMIFS(Table1[net_elec_imports],Table1[country],"Egypt",Table1[year],EnergyData!B42) -> -0.27 | C18: =SUMIFS(Table1[net_elec_imports_share_demand],Table1[country],"Egypt",Table1[year],EnergyData!B42)/100 -> -0.00144 | D18: =SUMIFS(Table1[gas_production],Table1[country],"Egypt",Table1[year],EnergyData!B42)-SUMIFS(Table1[gas_consumption],Table1[country],"Egypt",Table1[year],EnergyData!B42) -> -91.024 | E18: =SUMIFS(Table1[oil_production],Table1[country],"Egypt",Table1[year],EnergyData!B42)-SUMIFS(Table1[oil_consumption],Table1[country],"Egypt",Table1[year],EnergyData!B42) -> -86.677 | M18: 2009 | N18: 193.944 | O18: 6.413
A19: 2017 | B19: =SUMIFS(Table1[net_elec_imports],Table1[country],"Egypt",Table1[year],EnergyData!B43) -> -0.34 | C19: =SUMIFS(Table1[net_elec_imports_share_demand],Table1[country],"Egypt",Table1[year],EnergyData!B43)/100 -> -0.00176 | D19: =SUMIFS(Table1[gas_production],Table1[country],"Egypt",Table1[year],EnergyData!B43)-SUMIFS(Table1[gas_consumption],Table1[country],"Egypt",Table1[year],EnergyData!B43) -> -71.215 | E19: =SUMIFS(Table1[oil_production],Table1[country],"Egypt",Table1[year],EnergyData!B43)-SUMIFS(Table1[oil_consumption],Table1[country],"Egypt",Table1[year],EnergyData!B43) -> -81.986 | M19: 2010 | N19: 156.021 | O19: -8.195
A20: 2018 | B20: =SUMIFS(Table1[net_elec_imports],Table1[country],"Egypt",Table1[year],EnergyData!B44) -> -0.57 | C20: =SUMIFS(Table1[net_elec_imports_share_demand],Table1[country],"Egypt",Table1[year],EnergyData!B44)/100 -> -0.00287 | D20: =SUMIFS(Table1[gas_production],Table1[country],"Egypt",Table1[year],EnergyData!B44)-SUMIFS(Table1[gas_consumption],Table1[country],"Egypt",Table1[year],EnergyData!B44) -> -10.363 | E20: =SUMIFS(Table1[oil_production],Table1[country],"Egypt",Table1[year],EnergyData!B44)-SUMIFS(Table1[oil_consumption],Table1[country],"Egypt",Table1[year],EnergyData!B44) -> -24.469 | M20: 2011 | N20: 113.84 | O20: -15.836
... A25: 2023 | B25: =SUMIFS(Table1[net_elec_imports],Table1[country],"Egypt",Table1[year],EnergyData!B49) -> -1.39 | C25: =SUMIFS(Table1[net_elec_imports_share_demand],Table1[country],"Egypt",Table1[year],EnergyData!B49)/100 -> -0.0063 | D25: =SUMIFS(Table1[gas_production],Table1[country],"Egypt",Table1[year],EnergyData!B49)-SUMIFS(Table1[gas_consumption],Table1[country],"Egypt",Table1[year],EnergyData!B49) -> -29.386 | E25: =SUMIFS(Table1[oil_production],Table1[country],"Egypt",Table1[year],EnergyData!B49)-SUMIFS(Table1[oil_consumption],Table1[country],"Egypt",Table1[year],EnergyData!B49) -> -68.72 | M25: 2016 | N25: -91.024 | O25: -86.677
M26: 2017 | N26: -71.215 | O26: -81.986
M27: 2018 | N27: -10.363 | O27: -24.469
M28: 2019 | N28: 59.001 | O28: -13.64
B29: Country | C29: Net Elec Imports (TWh) | M29: 2020 | N29: 1.573 | O29: 28.622
B30: Algeria | C30: =SUMIFS(Table1[net_elec_imports],Table1[country],EnergyData!A25,Table1[year],EnergyData!B25) -> -2.44 | M30: 2021 | N30: 56.746 | O30: -15.303
B31: Egypt | C31: =SUMIFS(Table1[net_elec_imports],Table1[country],EnergyData!A49,Table1[year],EnergyData!B49) -> -1.39 | M31: 2022 | N31: 38.973 | O31: -75.836
B32: Ethiopia | C32: =SUMIFS(Table1[net_elec_imports],Table1[country],EnergyData!A73,Table1[year],EnergyData!B73) -> -1.78 | M32: 2023 | N32: -29.386 | O32: -68.72
B33: Iran | C33: =SUMIFS(Table1[net_elec_imports],Table1[country],EnergyData!A97,Table1[year],EnergyData!B97) -> -6.73 | M33: Grand Total | N33: 1177.313 | O33: 205.346
B34: Iraq | C34: =SUMIFS(Table1[net_elec_imports],Table1[country],EnergyData!A121,Table1[year],EnergyData!B121) -> 6.82
B35: Israel | C35: =SUMIFS(Table1[net_elec_imports],Table1[country],EnergyData!A145,Table1[year],EnergyData!B145) -> -6.93
B36: Jordan | C36: =SUMIFS(Table1[net_elec_imports],Table1[country],EnergyData!A169,Table1[year],EnergyData!B169) -> 0.07
B37: Libya | C37: =SUMIFS(Table1[net_elec_imports],Table1[country],EnergyData!A193,Table1[year],EnergyData!B193) -> 0
B38: Morocco | C38: =SUMIFS(Table1[net_elec_imports],Table1[country],EnergyData!A217,Table1[year],EnergyData!B217) -> 1.85
B39: Nigeria | C39: =SUMIFS(Table1[net_elec_imports],Table1[country],EnergyData!A241,Table1[year],EnergyData!B241) -> -2.32
B40: Saudi Arabia | C40: =SUMIFS(Table1[net_elec_imports],Table1[country],EnergyData!A265,Table1[year],EnergyData!B265) -> -0.04
B41: South Africa | C41: =SUMIFS(Table1[net_elec_imports],Table1[country],EnergyData!A289,Table1[year],EnergyData!B289) -> -0.55
B42: Sudan | C42: =SUMIFS(Table1[net_elec_imports],Table1[country],EnergyData!A313,Table1[year],EnergyData!B313) -> 0.65
B43: Tunisia | C43: =SUMIFS(Table1[net_elec_imports],Table1[country],EnergyData!A337,Table1[year],EnergyData!B337) -> 2.5
B44: Turkey | C44: =SUMIFS(Table1[net_elec_imports],Table1[country],EnergyData!A361,Table1[year],EnergyData!B361) -> 4.02
...

Sheet Electricity_Prices
C4: Consumption Tier (kWh/month) | D4: Residential Price (EGP/kWh) | E4: Effective Since
C5: 0–50 | D5: 0.68 | E5: Sep 2024
C6: 51–100 | D6: 0.78 | E6: Sep 2024
C7: 101–200 | D7: 0.95 | E7: Sep 2024
C8: 201–350 | D8: 1.55 | E8: Sep 2024
C9: 351–650 | D9: 1.95 | E9: Sep 2024
C10: 651–1000 | D10: 2.1 | E10: Sep 2024
C11: 1000+ | D11: 2.58 | E11: Apr 2026
C15: حاسبة تقديرية للفاتورة (أدخل الاستهلاك الشهري بالـ kWh):
C16: الاستهلاك الشهري (kWh) | D16: 350
C17: قيمة استهلاك الطاقة (EGP) | D17: 400.5
C18: مقابل خدمة العملاء الشهري (EGP) | D18: 11
C19: إجمالي الفاتورة التقديري (EGP) | D19: =D17+D18 -> 411.5

Sheet Electricity Price History
D6: Year | E6: First Tier Price (EGP/kWh, 0-50 kWh) | F6: Status | G6: Source
D7: 2000 | E7: 0.05 | F7: مؤكد | G7: Marefa — ثابت منذ 1993
D8: 2001 | E8: 0.05 | F8: مؤكد | G8: Marefa — ثابت منذ 1993
D9: 2002 | E9: 0.05 | F9: مؤكد | G9: Marefa — ثابت منذ 1993
D10: 2003 | E10: 0.05 | F10: مؤكد | G10: Marefa — ثابت منذ 1993
D11: 2004 | E11: 0.05 | F11: مؤكد | G11: Marefa — ثابت منذ 1993
D12: 2005 | E12: 0.05 | F12: مؤكد | G12: Marefa — ثابت منذ 1993
D13: 2006 | E13: 0.05 | F13: مؤكد | G13: Marefa — ثابت منذ 1993
D14: 2007 | E14: 0.05 | F14: مؤكد | G14: Marefa — ثابت منذ 1993
D15: 2008 | E15: 0.05 | F15: مؤكد | G15: Marefa — ثابت منذ 1993
D16: 2009 | E16: 0.05 | F16: مؤكد | G16: Marefa — ثابت منذ 1993
D17: 2010 | E17: 0.05 | F17: مؤكد | G17: Marefa — ثابت منذ 1993
D18: 2011 | E18: 0.05 | F18: مؤكد | G18: Marefa — ثابت منذ 1993
... D20: 2013 | E20: 0.05 | F20: مؤكد | G20: Marefa — ثابت منذ 1993
D21: 2014 | E21: 0.075 | F21: مؤكد | G21: Masrawy — بداية خطة رفع الدعم (يوليو 2014) | N21: Row Labels | O21: Sum of First Tier Price (EGP/kWh, 0-50 kWh)
D22: 2015 | E22: 0.075 | F22: غير مؤكد | G22: زيادة سنوية جزء من خطة 5 سنوات — الرقم الدقيق غير متاح رغم بحث إضافي | N22: 2000 | O22: 0.05
D23: 2016 | E23: 0.1 | F23: غير مؤكد | G23: زيادة سنوية جزء من خطة 5 سنوات — الرقم الدقيق غير متاح رغم بحث إضافي | N23: 2001 | O23: 0.05
D24: 2017 | E24: 0.13 | F24: غير مؤكد | G24: زيادة سنوية جزء من خطة 5 سنوات — الرقم الدقيق غير متاح رغم بحث إضافي | N24: 2002 | O24: 0.05
D25: 2018 | E25: 0.22 | F25: مؤكد | G25: Masrawy (فبراير 2020) — مذكور كسعر سابق مقارنةً بـ2019 | N25: 2003 | O25: 0.05
D26: 2019 | E26: 0.3 | F26: مؤكد | G26: Masrawy (فبراير 2020) + Alghad.tv (يونيو 2020) — مؤكد من مصدرين | N26: 2004 | O26: 0.05
D27: 2020 | E27: 0.38 | F27: مؤكد | G27: Alghad.tv (يونيو 2020) | N27: 2005 | O27: 0.05
D28: 2021 | E28: 0.48 | F28: مؤكد | G28: Marefa/Almasryalyoum — مقارنة FY2021/22 | N28: 2006 | O28: 0.05
D29: 2022 | E29: 0.58 | F29: مؤكد | G29: Marefa (تعريفة يوليو 2022) | N29: 2007 | O29: 0.05
D30: 2023 | E30: 0.68 | F30: مؤكد | G30: Marefa (تعريفة يوليو 2023) — ثابت حتى أبريل 2026 | N30: 2008 | O30: 0.05
N31: 2009 | O31: 0.05
N32: 2010 | O32: 0.05
N33: 2011 | O33: 0.05
N34: 2012 | O34: 0.05
N35: 2013 | O35: 0.05
N36: 2014 | O36: 0.075
N37: 2015 | O37: 0.075
N38: 2016 | O38: 0.1
N39: 2017 | O39: 0.13
N40: 2018 | O40: 0.22
N41: 2019 | O41: 0.3
N42: 2020 | O42: 0.38
... N45: 2023 | O45: 0.68
N46: Grand Total | O46: 3.72

Sheet Dashboard
